const p1 = new Promise((resolve, reject) => {
    setTimeout(() => resolve('hello'), 100)
  })
  .then(result => result)
  .catch(e => e);
  
  const p2 = new Promise((resolve, reject) => {
    throw new Error('报错了');
  })
  .then(result => result)
  .catch(e => e);
  
  // 上面的promise已经catch，不会被Promise.all捕获
  Promise.all([p1, p2])
  .then(result => console.log(result))
  .catch(e => console.log(e));
  // ["hello", Error: 报错了]

  